Total Instances: 81

Total Correct: 67
Total Runtime Failed: 3
Total Compilation Failed: 3
Total Test Failed: 7
Total Infinite Loop: 1

Accuracy: 82.71604938271605
Runtime Rate: 3.7037037037037033
Compilation Rate: 3.7037037037037033
Test Failed Rate: 8.641975308641975
Infinite Loop Rate: 1.2345679012345678

=================================================================================================
Failed Test Files: ['atcoder_ABC149_B.py', 'codeforces_622_A.py', 'atcoder_ARC062_B.py', 'codeforces_58_B.py', 'codeforces_8_B.py', 'codeforces_79_A.py', 'codeforces_92_A.py'] 
Failed Test Details: ['Filename: codeforces_58_B.py Actual: 733035 \n244345 \n48869 \n1  Generated: 733035 244345 48869 1 ', 'Filename: atcoder_ARC062_B.py Actual: 0\n Generated: -1\n', 'Filename: codeforces_92_A.py Actual: 9\n Generated: ', 'Filename: atcoder_ABC149_B.py Actual: 0 1000000000000 Generated: ', 'Filename: codeforces_8_B.py Actual: BUG\n Generated: Enter the path: BUG\n', 'Filename: codeforces_622_A.py Actual: 311 Generated: 311\n99992\n', 'Filename: codeforces_79_A.py Actual: Ciel\n Generated: '] 
=================================================================================================
Runtime Error Files: ['atcoder_ABC132_F.py', 'codeforces_99_A.py', 'atcoder_ABC051_A.py'] 
Runtime Error Details: ['Filename: atcoder_ABC051_A.py Error_type: Traceback (most recent call last):\n  File "/home/ali/Documents/CodeMind/translation_output/w_test/gpt-4/avatar/java/python-sanitized/atcoder_ABC051_A.py", line 5, in <module>\n    a, b, c = input_string.split(\',\')\nValueError: too many values to unpack (expected 3)\n', 'Filename: codeforces_99_A.py Error_type: Traceback (most recent call last):\n  File "/home/ali/Documents/CodeMind/translation_output/w_test/gpt-4/avatar/java/python-sanitized/codeforces_99_A.py", line 41, in <module>\n    main()\n  File "/home/ali/Documents/CodeMind/translation_output/w_test/gpt-4/avatar/java/python-sanitized/codeforces_99_A.py", line 5, in main\n    input_file = open("/home/changshu/CodeMind/dataset/Avatar/Avatar-java/codeforces_99_A/input.txt", "r")\nPermissionError: [Errno 13] Permission denied: \'/home/changshu/CodeMind/dataset/Avatar/Avatar-java/codeforces_99_A/input.txt\'\n', 'Filename: atcoder_ABC132_F.py Error_type: Traceback (most recent call last):\n  File "/home/ali/Documents/CodeMind/translation_output/w_test/gpt-4/avatar/java/python-sanitized/atcoder_ABC132_F.py", line 26, in <module>\n    main()\n  File "/home/ali/Documents/CodeMind/translation_output/w_test/gpt-4/avatar/java/python-sanitized/atcoder_ABC132_F.py", line 12, in main\n    q = len(len)\nTypeError: \'list\' object is not callable\n'] 
=================================================================================================
Compilation Error Files: ['codeforces_30_A.py', 'atcoder_AGC046_A.py', 'atcoder_AGC007_C.py'] 
=================================================================================================
Infinite Loop Files: ['codeforces_669_A.py'] 
=================================================================================================
