Total Instances: 86

Total Correct: 54
Total Runtime Failed: 21
Total Compilation Failed: 2
Total Test Failed: 8
Total Infinite Loop: 1

Accuracy: 62.7906976744186
Runtime Rate: 24.418604651162788
Compilation Rate: 2.3255813953488373
Test Failed Rate: 9.30232558139535
Infinite Loop Rate: 1.1627906976744187

=================================================================================================
Failed Test Files: ['atcoder_AGC046_A.py', 'codeforces_340_A.py', 'codeforces_514_A.py', 'codeforces_306_A.py', 'atcoder_ARC062_B.py', 'atcoder_ABC051_A.py', 'codeforces_58_B.py', 'atcoder_ABC155_E.py'] 
Failed Test Details: ['Filename: atcoder_ARC062_B.py Actual: 0\n Generated: -1\n', 'Filename: codeforces_58_B.py Actual: 733035 \n244345 \n48869 \n1  Generated: 733035 244345 48869 1 ', 'Filename: codeforces_340_A.py Actual: 1000000000\n Generated: 0\n', 'Filename: atcoder_ABC155_E.py Actual: 1\n Generated: ', 'Filename: codeforces_514_A.py Actual: 4221\n Generated: 1224\n', 'Filename: atcoder_AGC046_A.py Actual: 360\n Generated: Enter an integer: 360\n', 'Filename: atcoder_ABC051_A.py Actual: pnxnn asadasd asdasf\n\n Generated: ', 'Filename: codeforces_306_A.py Actual: 2 2 2 2 2 2 2 2 2 2 2 2 2 2 2 3 3 3 3 3 3 3 3 3 3 3 3 3 3 3 3 3 3 3  Generated: '] 
=================================================================================================
Runtime Error Files: ['codeforces_544_B.py', 'codeforces_546_A.py', 'codeforces_203_A.py', 'atcoder_ABC168_C.py', 'codeforces_171_A.py', 'atcoder_ARC102_C.py', 'codeforces_651_A.py', 'atcoder_ABC158_B.py', 'atcoder_ABC153_A.py', 'atcoder_ABC070_B.py', 'atcoder_AGC002_A.py', 'codeforces_30_A.py', 'atcoder_ABC127_B.py', 'codeforces_189_A.py', 'atcoder_ABC132_F.py', 'atcoder_ABC042_A.py', 'atcoder_ABC125_A.py', 'atcoder_ABC169_C.py', 'codeforces_569_A.py', 'atcoder_ABC143_A.py', 'codeforces_86_A.py'] 
Runtime Error Details: ['Filename: codeforces_30_A.py Error_type: Traceback (most recent call last):\n  File "/home/ali/Documents/CodeMind/translation_output/gpt-4/avatar/java/python-sanitized/codeforces_30_A.py", line 4, in <module>\n    A = int(input())\nValueError: invalid literal for int() with base 10: \'7 896 7\'\n', 'Filename: codeforces_171_A.py Error_type: Traceback (most recent call last):\n  File "/home/ali/Documents/CodeMind/translation_output/gpt-4/avatar/java/python-sanitized/codeforces_171_A.py", line 9, in <module>\n    a = int(input())\nValueError: invalid literal for int() with base 10: \'35005211 521595368\'\n', 'Filename: codeforces_203_A.py Error_type: Traceback (most recent call last):\n  File "/home/ali/Documents/CodeMind/translation_output/gpt-4/avatar/java/python-sanitized/codeforces_203_A.py", line 47, in <module>\n    main()\n  File "/home/ali/Documents/CodeMind/translation_output/gpt-4/avatar/java/python-sanitized/codeforces_203_A.py", line 43, in main\n    ATwoProblems_instance.solve(1, in_stream, out_stream)\n  File "/home/ali/Documents/CodeMind/translation_output/gpt-4/avatar/java/python-sanitized/codeforces_203_A.py", line 5, in solve\n    points = in_stream.get_int()\n  File "/home/ali/Documents/CodeMind/translation_output/gpt-4/avatar/java/python-sanitized/codeforces_203_A.py", line 28, in get_int\n    return int(self.get_next_token())\nTypeError: int() argument must be a string, a bytes-like object or a real number, not \'generator\'\n', 'Filename: atcoder_ABC127_B.py Error_type: Traceback (most recent call last):\n  File "/home/ali/Documents/CodeMind/translation_output/gpt-4/avatar/java/python-sanitized/atcoder_ABC127_B.py", line 10, in <module>\n    atcoder_ABC127_B()\n  File "/home/ali/Documents/CodeMind/translation_output/gpt-4/avatar/java/python-sanitized/atcoder_ABC127_B.py", line 2, in atcoder_ABC127_B\n    r = int(input())\nValueError: invalid literal for int() with base 10: \'2 1 2\'\n', 'Filename: codeforces_569_A.py Error_type: Traceback (most recent call last):\n  File "/home/ali/Documents/CodeMind/translation_output/gpt-4/avatar/java/python-sanitized/codeforces_569_A.py", line 62, in <module>\n    main()\n  File "/home/ali/Documents/CodeMind/translation_output/gpt-4/avatar/java/python-sanitized/codeforces_569_A.py", line 59, in main\n    solver.solve(1, in_reader, output_stream)\n  File "/home/ali/Documents/CodeMind/translation_output/gpt-4/avatar/java/python-sanitized/codeforces_569_A.py", line 45, in solve\n    t = in_reader.next_int()\n  File "/home/ali/Documents/CodeMind/translation_output/gpt-4/avatar/java/python-sanitized/codeforces_569_A.py", line 29, in next_int\n    return int(self.next())\n  File "/home/ali/Documents/CodeMind/translation_output/gpt-4/avatar/java/python-sanitized/codeforces_569_A.py", line 22, in next\n    self._tokenize()\n  File "/home/ali/Documents/CodeMind/translation_output/gpt-4/avatar/java/python-sanitized/codeforces_569_A.py", line 11, in _tokenize\n    self.tokenizer = self.reader.readline().strip().split()\nAttributeError: \'_io.TextIOWrapper\' object has no attribute \'readinto\'. Did you mean: \'readline\'?\n', 'Filename: atcoder_ABC132_F.py Error_type: Traceback (most recent call last):\n  File "/home/ali/Documents/CodeMind/translation_output/gpt-4/avatar/java/python-sanitized/atcoder_ABC132_F.py", line 36, in <module>\n    atcoder_ABC132_F()\n  File "/home/ali/Documents/CodeMind/translation_output/gpt-4/avatar/java/python-sanitized/atcoder_ABC132_F.py", line 16, in atcoder_ABC132_F\n    q = len(len)\nTypeError: \'list\' object is not callable\n', 'Filename: atcoder_ARC102_C.py Error_type: Traceback (most recent call last):\n  File "/home/ali/Documents/CodeMind/translation_output/gpt-4/avatar/java/python-sanitized/atcoder_ARC102_C.py", line 11, in <module>\n    k = int(input())\nValueError: invalid literal for int() with base 10: \'1 200000\'\n', 'Filename: codeforces_189_A.py Error_type: Traceback (most recent call last):\n  File "/home/ali/Documents/CodeMind/translation_output/gpt-4/avatar/java/python-sanitized/codeforces_189_A.py", line 14, in <module>\n    main()\n  File "/home/ali/Documents/CodeMind/translation_output/gpt-4/avatar/java/python-sanitized/codeforces_189_A.py", line 2, in main\n    n = int(input())\nValueError: invalid literal for int() with base 10: \'29 27 18 2\'\n', 'Filename: codeforces_651_A.py Error_type: Traceback (most recent call last):\n  File "/home/ali/Documents/CodeMind/translation_output/gpt-4/avatar/java/python-sanitized/codeforces_651_A.py", line 1, in <module>\n    num1 = int(input())\nValueError: invalid literal for int() with base 10: \'100 25\'\n', 'Filename: atcoder_ABC153_A.py Error_type: Traceback (most recent call last):\n  File "/home/ali/Documents/CodeMind/translation_output/gpt-4/avatar/java/python-sanitized/atcoder_ABC153_A.py", line 13, in <module>\n    atcoder_ABC153_A()\n  File "/home/ali/Documents/CodeMind/translation_output/gpt-4/avatar/java/python-sanitized/atcoder_ABC153_A.py", line 2, in atcoder_ABC153_A\n    monsterHP = int(input())\nValueError: invalid literal for int() with base 10: \'10000 1\'\n', 'Filename: atcoder_ABC158_B.py Error_type: Traceback (most recent call last):\n  File "/home/ali/Documents/CodeMind/translation_output/gpt-4/avatar/java/python-sanitized/atcoder_ABC158_B.py", line 16, in <module>\n    main()\n  File "/home/ali/Documents/CodeMind/translation_output/gpt-4/avatar/java/python-sanitized/atcoder_ABC158_B.py", line 9, in main\n    N = int(input())\nValueError: invalid literal for int() with base 10: \'501719768609305159 370614275896614890 131105492712690269\'\n', 'Filename: atcoder_ABC070_B.py Error_type: Traceback (most recent call last):\n  File "/home/ali/Documents/CodeMind/translation_output/gpt-4/avatar/java/python-sanitized/atcoder_ABC070_B.py", line 19, in <module>\n    atcoder_ABC070_B()\n  File "/home/ali/Documents/CodeMind/translation_output/gpt-4/avatar/java/python-sanitized/atcoder_ABC070_B.py", line 2, in atcoder_ABC070_B\n    a = int(input())\nValueError: invalid literal for int() with base 10: \'0 50 50 100\'\n', 'Filename: atcoder_ABC143_A.py Error_type: Traceback (most recent call last):\n  File "/home/ali/Documents/CodeMind/translation_output/gpt-4/avatar/java/python-sanitized/atcoder_ABC143_A.py", line 15, in <module>\n    atcoder_ABC143_A()\n  File "/home/ali/Documents/CodeMind/translation_output/gpt-4/avatar/java/python-sanitized/atcoder_ABC143_A.py", line 4, in atcoder_ABC143_A\n    A = int(input())  # Reading integer input in Python\nValueError: invalid literal for int() with base 10: \'75 25\'\n', 'Filename: codeforces_544_B.py Error_type: Traceback (most recent call last):\n  File "/home/ali/Documents/CodeMind/translation_output/gpt-4/avatar/java/python-sanitized/codeforces_544_B.py", line 26, in <module>\n    main()\n  File "/home/ali/Documents/CodeMind/translation_output/gpt-4/avatar/java/python-sanitized/codeforces_544_B.py", line 22, in main\n    n = int(input())\nValueError: invalid literal for int() with base 10: \'100 10000\'\n', 'Filename: atcoder_ABC168_C.py Error_type: Traceback (most recent call last):\n  File "/home/ali/Documents/CodeMind/translation_output/gpt-4/avatar/java/python-sanitized/atcoder_ABC168_C.py", line 3, in <module>\n    a = int(input())\nValueError: invalid literal for int() with base 10: \'1 2 9 49\'\n', 'Filename: atcoder_ABC125_A.py Error_type: Traceback (most recent call last):\n  File "/home/ali/Documents/CodeMind/translation_output/gpt-4/avatar/java/python-sanitized/atcoder_ABC125_A.py", line 10, in <module>\n    atcoder_ABC125_A()\n  File "/home/ali/Documents/CodeMind/translation_output/gpt-4/avatar/java/python-sanitized/atcoder_ABC125_A.py", line 2, in atcoder_ABC125_A\n    a = int(input())\nValueError: invalid literal for int() with base 10: \'20 20 19\'\n', 'Filename: atcoder_ABC169_C.py Error_type: Traceback (most recent call last):\n  File "/home/ali/Documents/CodeMind/translation_output/gpt-4/avatar/java/python-sanitized/atcoder_ABC169_C.py", line 11, in <module>\n    atcoder_ABC169_C()\n  File "/home/ali/Documents/CodeMind/translation_output/gpt-4/avatar/java/python-sanitized/atcoder_ABC169_C.py", line 4, in atcoder_ABC169_C\n    a = int(input())\nValueError: invalid literal for int() with base 10: \'814793613347395 1.99\'\n', 'Filename: codeforces_546_A.py Error_type: Traceback (most recent call last):\n  File "/home/ali/Documents/CodeMind/translation_output/gpt-4/avatar/java/python-sanitized/codeforces_546_A.py", line 3, in <module>\n    o = int(input())\nValueError: invalid literal for int() with base 10: \'1000 1000000000 1000\'\n', 'Filename: codeforces_86_A.py Error_type: Traceback (most recent call last):\n  File "/home/ali/Documents/CodeMind/translation_output/gpt-4/avatar/java/python-sanitized/codeforces_86_A.py", line 34, in <module>\n    main()\n  File "/home/ali/Documents/CodeMind/translation_output/gpt-4/avatar/java/python-sanitized/codeforces_86_A.py", line 16, in main\n    l = int(input())\nValueError: invalid literal for int() with base 10: \'999999999 999999999\'\n', 'Filename: atcoder_ABC042_A.py Error_type: Traceback (most recent call last):\n  File "/home/ali/Documents/CodeMind/translation_output/gpt-4/avatar/java/python-sanitized/atcoder_ABC042_A.py", line 15, in <module>\n    atcoder_ABC042_A()\n  File "/home/ali/Documents/CodeMind/translation_output/gpt-4/avatar/java/python-sanitized/atcoder_ABC042_A.py", line 2, in atcoder_ABC042_A\n    num_1 = int(input())\nValueError: invalid literal for int() with base 10: \'5 5 7\'\n', 'Filename: atcoder_AGC002_A.py Error_type: Traceback (most recent call last):\n  File "/home/ali/Documents/CodeMind/translation_output/gpt-4/avatar/java/python-sanitized/atcoder_AGC002_A.py", line 4, in <module>\n    a = int(input())\nValueError: invalid literal for int() with base 10: \'-1000000000 -1\'\n'] 
=================================================================================================
Compilation Error Files: ['atcoder_AGC007_C.py', 'codeforces_99_A.py'] 
=================================================================================================
Infinite Loop Files: ['codeforces_669_A.py'] 
=================================================================================================
